<?xml version="1.0" ?>
<!-- =================================================================================== -->
<!-- |    Chassis for the robot Jaguar V2 - - - Versionado por Jorge                   | -->
<!-- |    Jorge De Leon Rivas - - - jorge.deleon@upm.es                                | -->
<!-- |    September / 6 / 2018                                                         | -->
<!-- =================================================================================== -->

<robot name="flipper" xmlns:xacro="http://ros.org/wiki/xacro">

<!-- Colors -->
<material name="black">
  <color rgba="0.0 0.0 0.0 1.0"/>
</material>

<!-- Constants -->
<xacro:property name="flipper_max_effort"       value="100"   />
<xacro:property name="flipper_max_position"     value="-6.283"/>
<xacro:property name="flipper_min_position"     value="6.283" />
<xacro:property name="flipper_max_revolution"   value="100"   />


<xacro:macro name="flipper" params="name parent_link right *origin">

    <!--=====================================================================-->
    <!--        Definition of the flippers of the robot                      -->
    <!--=====================================================================-->

    <!-- Link of the Flipper -->
    <link name="${name}_flipper_link">
        <inertial>
            <origin xyz="0 0 0" rpy="0 0 0"/>
            <mass value="0.775"/>
            <inertia ixx="${1}"
                     ixy="${0}"     iyy="${1}"
                     ixz="${0}"     iyz="${0}"      izz="${1}"/>
        </inertial>

        <visual>
            <origin xyz="0 0 0" rpy="${0} 0 0"/>
            <geometry>
                <mesh filename="package://eng_description/meshes/Flipper.dae" scale="0.1 0.1 0.1"/>
            </geometry>
            <material name="Black"/>
        </visual>

        <collision>
            <origin rpy="0 0 0" xyz="0 0 0"/>
            <geometry>
                <mesh filename="package://eng_description/meshes/Flipper.dae" scale="0.1 0.1 0.1"/>
            </geometry>
        </collision>
    </link>

    <!-- Joint of the Flipper -->
    <joint name="${name}_flipper_to_${parent_link}_joint" type="revolute">
        <xacro:insert_block name="origin"/>
        <parent link="${parent_link}"/>
        <child link="${name}_flipper_link"/>
        <axis xyz="1 0 0"/>
        <limit effort="${flipper_max_effort}" velocity="${flipper_max_revolution}" lower="${flipper_max_position}" upper="${flipper_min_position}"/> <!-- Nm rads/s -->
    </joint>

    <!-- Transmission of the Flipper -->
    <transmission name="${name}_flipper_transmission">
        <type>transmission_interface/SimpleTransmission</type>
        <joint name="${name}_flipper_to_${parent_link}_joint">
            <hardwareInterface>hardware_interface/EffortJointInterface</hardwareInterface>
        </joint>
        <actuator name="${name}_motor_joint_flipper">
            <mechanicalReduction>1</mechanicalReduction>
            <hardwareInterface>EffortJointInterface</hardwareInterface>
        </actuator>
    </transmission>

</xacro:macro>

</robot>
